<sdf version='1.7'>
  <world name='default'>
    <model name='ground_plane'>
      <static>1</static>
      <link name='link'>
        <collision name='collision'>
          <geometry>
            <plane>
              <normal>0 0 1</normal>
              <size>100 100</size>
            </plane>
          </geometry>
          <surface>
            <contact>
              <collide_bitmask>65535</collide_bitmask>
              <ode/>
            </contact>
            <friction>
              <ode>
                <mu>100</mu>
                <mu2>50</mu2>
              </ode>
              <torsional>
                <ode/>
              </torsional>
            </friction>
            <bounce/>
          </surface>
          <max_contacts>10</max_contacts>
        </collision>
        <visual name='visual'>
          <cast_shadows>0</cast_shadows>
          <geometry>
            <plane>
              <normal>0 0 1</normal>
              <size>100 100</size>
            </plane>
          </geometry>
          <material>
            <script>
              <uri>file://media/materials/scripts/gazebo.material</uri>
              <name>Gazebo/Grey</name>
            </script>
          </material>
        </visual>
        <self_collide>0</self_collide>
        <enable_wind>0</enable_wind>
        <kinematic>0</kinematic>
      </link>
      <pose>0 0 -0.18 0 -0 0</pose>
    </model>
    <light name='sun' type='directional'>
      <cast_shadows>1</cast_shadows>
      <pose>0 0 10 0 -0 0</pose>
      <diffuse>0.8 0.8 0.8 1</diffuse>
      <specular>0.2 0.2 0.2 1</specular>
      <attenuation>
        <range>1000</range>
        <constant>0.9</constant>
        <linear>0.01</linear>
        <quadratic>0.001</quadratic>
      </attenuation>
      <direction>-0.5 0.1 -0.9</direction>
      <spot>
        <inner_angle>0</inner_angle>
        <outer_angle>0</outer_angle>
        <falloff>0</falloff>
      </spot>
    </light>
    <gravity>0 0 -9.81</gravity>
    <physics type='ode'>
      <max_step_size>0.001</max_step_size>
      <real_time_factor>1</real_time_factor>
      <real_time_update_rate>1000</real_time_update_rate>
    </physics>
    <magnetic_field>6e-06 2.3e-05 -4.2e-05</magnetic_field>
    <atmosphere type='adiabatic'/>
    <scene>
      <ambient>0.4 0.4 0.4 1</ambient>
      <background>0.7 0.7 0.7 1</background>
      <shadows>1</shadows>
    </scene>
    <wind/>
    <spherical_coordinates>
      <surface_model>EARTH_WGS84</surface_model>
      <latitude_deg>0</latitude_deg>
      <longitude_deg>0</longitude_deg>
      <elevation>0</elevation>
      <heading_deg>0</heading_deg>
    </spherical_coordinates>
    <model name='iiwas_frame'>
      <joint name='iiwa_frame_origin_joint' type='fixed'>
        <pose relative_to='__model__'>-0.048 -0.076 0 0 -0 0</pose>
        <parent>world</parent>
        <child>iiwa_frame_origin</child>
      </joint>
      <link name='iiwa_frame_origin'>
        <pose relative_to='iiwa_frame_origin_joint'>0 0 0 0 -0 0</pose>
        <inertial>
          <pose>1.74778 0.9 -0.0825 0 -0 0</pose>
          <mass>36</mass>
          <inertia>
            <ixx>11.4086</ixx>
            <ixy>2.13163e-14</ixy>
            <ixz>0</ixz>
            <iyy>72.8956</iyy>
            <iyz>0</iyz>
            <izz>84.1492</izz>
          </inertia>
        </inertial>
        <collision name='iiwa_frame_origin_fixed_joint_lump__h_bar_back_in_collision'>
          <pose>3.246 0.9 -0.0825 0 -0 0</pose>
          <geometry>
            <box>
              <size>0.12 1.56 0.165</size>
            </box>
          </geometry>
          <surface>
            <contact>
              <ode/>
            </contact>
            <bounce/>
            <friction>
              <torsional>
                <ode/>
              </torsional>
              <ode/>
            </friction>
          </surface>
          <max_contacts>10</max_contacts>
        </collision>
        <collision name='iiwa_frame_origin_fixed_joint_lump__h_bar_front_in_collision_1'>
          <pose>0.238 0.9 -0.0825 0 -0 0</pose>
          <geometry>
            <box>
              <size>0.12 1.56 0.165</size>
            </box>
          </geometry>
          <surface>
            <contact>
              <ode/>
            </contact>
            <bounce/>
            <friction>
              <torsional>
                <ode/>
              </torsional>
              <ode/>
            </friction>
          </surface>
          <max_contacts>10</max_contacts>
        </collision>
        <collision name='iiwa_frame_origin_fixed_joint_lump__h_bar_front_out_collision_2'>
          <pose>0.04 0.9 -0.0825 0 -0 0</pose>
          <geometry>
            <box>
              <size>0.08 1.56 0.165</size>
            </box>
          </geometry>
          <surface>
            <contact>
              <ode/>
            </contact>
            <bounce/>
            <friction>
              <torsional>
                <ode/>
              </torsional>
              <ode/>
            </friction>
          </surface>
          <max_contacts>10</max_contacts>
        </collision>
        <collision name='iiwa_frame_origin_fixed_joint_lump__v_bar_right_collision_3'>
          <pose>1.75 0.06 -0.0825 0 -0 0</pose>
          <geometry>
            <box>
              <size>3.5 0.12 0.165</size>
            </box>
          </geometry>
          <surface>
            <contact>
              <ode/>
            </contact>
            <bounce/>
            <friction>
              <torsional>
                <ode/>
              </torsional>
              <ode/>
            </friction>
          </surface>
          <max_contacts>10</max_contacts>
        </collision>
        <collision name='iiwa_frame_origin_fixed_joint_lump__h_bar_back_out_collision_4'>
          <pose>3.46 0.9 -0.0825 0 -0 0</pose>
          <geometry>
            <box>
              <size>0.08 1.56 0.165</size>
            </box>
          </geometry>
          <surface>
            <contact>
              <ode/>
            </contact>
            <bounce/>
            <friction>
              <torsional>
                <ode/>
              </torsional>
              <ode/>
            </friction>
          </surface>
          <max_contacts>10</max_contacts>
        </collision>
        <collision name='iiwa_frame_origin_fixed_joint_lump__v_bar_left_collision_5'>
          <pose>1.75 1.74 -0.0825 0 -0 3.14159</pose>
          <geometry>
            <box>
              <size>3.5 0.12 0.165</size>
            </box>
          </geometry>
          <surface>
            <contact>
              <ode/>
            </contact>
            <bounce/>
            <friction>
              <torsional>
                <ode/>
              </torsional>
              <ode/>
            </friction>
          </surface>
          <max_contacts>10</max_contacts>
        </collision>
        <visual name='iiwa_frame_origin_fixed_joint_lump__h_bar_back_in_visual'>
          <pose>3.246 0.9 -0.0825 0 -0 0</pose>
          <geometry>
            <box>
              <size>0.12 1.56 0.165</size>
            </box>
          </geometry>
        </visual>
        <visual name='iiwa_frame_origin_fixed_joint_lump__h_bar_front_in_visual_1'>
          <pose>0.238 0.9 -0.0825 0 -0 0</pose>
          <geometry>
            <box>
              <size>0.12 1.56 0.165</size>
            </box>
          </geometry>
        </visual>
        <visual name='iiwa_frame_origin_fixed_joint_lump__h_bar_front_out_visual_2'>
          <pose>0.04 0.9 -0.0825 0 -0 0</pose>
          <geometry>
            <box>
              <size>0.08 1.56 0.165</size>
            </box>
          </geometry>
        </visual>
        <visual name='iiwa_frame_origin_fixed_joint_lump__v_bar_right_visual_3'>
          <pose>1.75 0.06 -0.0825 0 -0 0</pose>
          <geometry>
            <box>
              <size>3.5 0.12 0.165</size>
            </box>
          </geometry>
        </visual>
        <visual name='iiwa_frame_origin_fixed_joint_lump__h_bar_back_out_visual_4'>
          <pose>3.46 0.9 -0.0825 0 -0 0</pose>
          <geometry>
            <box>
              <size>0.08 1.56 0.165</size>
            </box>
          </geometry>
        </visual>
        <visual name='iiwa_frame_origin_fixed_joint_lump__v_bar_left_visual_5'>
          <pose>1.75 1.74 -0.0825 0 -0 3.14159</pose>
          <geometry>
            <box>
              <size>3.5 0.12 0.165</size>
            </box>
          </geometry>
        </visual>
        <self_collide>0</self_collide>
        <enable_wind>0</enable_wind>
        <kinematic>0</kinematic>
      </link>
      <joint name='back_base_joint' type='fixed'>
        <pose relative_to='iiwa_frame_origin'>3.246 0.889 0.015 0 -0 3.14159</pose>
        <parent>iiwa_frame_origin</parent>
        <child>back_base</child>
        <axis>
          <dynamics>
            <spring_reference>0</spring_reference>
            <spring_stiffness>0</spring_stiffness>
          </dynamics>
          <xyz>0 0 1</xyz>
          <limit>
            <lower>-1e+16</lower>
            <upper>1e+16</upper>
          </limit>
        </axis>
        <physics>
          <ode>
            <limit>
              <cfm>0</cfm>
              <erp>0.2</erp>
            </limit>
          </ode>
        </physics>
      </joint>
      <link name='back_base'>
        <pose relative_to='back_base_joint'>0 0 0 0 -0 0</pose>
        <inertial>
          <pose>0 0 0 0 -0 0</pose>
          <mass>3</mass>
          <inertia>
            <ixx>0.03</ixx>
            <ixy>0</ixy>
            <ixz>0</ixz>
            <iyy>0.03</iyy>
            <iyz>0</iyz>
            <izz>0.06</izz>
          </inertia>
        </inertial>
        <collision name='back_base_collision'>
          <pose>0 0 0 0 -0 0</pose>
          <geometry>
            <box>
              <size>0.35 0.35 0.03</size>
            </box>
          </geometry>
          <surface>
            <contact>
              <ode/>
            </contact>
            <bounce/>
            <friction>
              <torsional>
                <ode/>
              </torsional>
              <ode/>
            </friction>
          </surface>
          <max_contacts>10</max_contacts>
        </collision>
        <visual name='back_base_visual'>
          <pose>0 0 0 0 -0 0</pose>
          <geometry>
            <box>
              <size>0.35 0.35 0.03</size>
            </box>
          </geometry>
        </visual>
        <gravity>1</gravity>
        <velocity_decay/>
        <self_collide>0</self_collide>
        <enable_wind>0</enable_wind>
        <kinematic>0</kinematic>
      </link>
      <joint name='front_base_joint' type='fixed'>
        <pose relative_to='iiwa_frame_origin'>0.238 0.889 0.015 0 -0 0</pose>
        <parent>iiwa_frame_origin</parent>
        <child>front_base</child>
        <axis>
          <dynamics>
            <spring_reference>0</spring_reference>
            <spring_stiffness>0</spring_stiffness>
          </dynamics>
          <xyz>0 0 1</xyz>
          <limit>
            <lower>-1e+16</lower>
            <upper>1e+16</upper>
          </limit>
        </axis>
        <physics>
          <ode>
            <limit>
              <cfm>0</cfm>
              <erp>0.2</erp>
            </limit>
          </ode>
        </physics>
      </joint>
      <link name='front_base'>
        <pose relative_to='front_base_joint'>0 0 0 0 -0 0</pose>
        <inertial>
          <pose>0 0 0 0 -0 0</pose>
          <mass>3</mass>
          <inertia>
            <ixx>0.03</ixx>
            <ixy>0</ixy>
            <ixz>0</ixz>
            <iyy>0.03</iyy>
            <iyz>0</iyz>
            <izz>0.06</izz>
          </inertia>
        </inertial>
        <collision name='front_base_collision'>
          <pose>0 0 0 0 -0 0</pose>
          <geometry>
            <box>
              <size>0.35 0.35 0.03</size>
            </box>
          </geometry>
          <surface>
            <contact>
              <ode/>
            </contact>
            <bounce/>
            <friction>
              <torsional>
                <ode/>
              </torsional>
              <ode/>
            </friction>
          </surface>
          <max_contacts>10</max_contacts>
        </collision>
        <visual name='front_base_visual'>
          <pose>0 0 0 0 -0 0</pose>
          <geometry>
            <box>
              <size>0.35 0.35 0.03</size>
            </box>
          </geometry>
        </visual>
        <gravity>1</gravity>
        <velocity_decay/>
        <self_collide>0</self_collide>
        <enable_wind>0</enable_wind>
        <kinematic>0</kinematic>
      </link>
      <static>0</static>
      <plugin name='gazebo_ros_control' filename='libgazebo_ros_control.so'>
        <robotNamespace>/iiwas_frame/</robotNamespace>
      </plugin>
      <pose>0 0 0 0 -0 0</pose>
    </model>
    <model name='iiwa_front'>
      <link name='front_base'>
        <inertial>
          <pose>-0.1 0 0.085 0 -0 0</pose>
          <mass>5</mass>
          <inertia>
            <ixx>0.05</ixx>
            <ixy>0</ixy>
            <ixz>-6.93889e-18</ixz>
            <iyy>0.06</iyy>
            <iyz>0</iyz>
            <izz>0.03</izz>
          </inertia>
        </inertial>
        <collision name='front_base_fixed_joint_lump__F_link_0_collision'>
          <pose>0 0 0.015 0 -0 0</pose>
          <geometry>
            <mesh>
              <scale>1 1 1</scale>
              <uri>/home/puze/catkin_ws/src/iiwas_core/iiwas_description/meshes/collision/link_0.stl</uri>
            </mesh>
          </geometry>
          <surface>
            <contact>
              <ode/>
            </contact>
            <friction>
              <ode>
                <mu>0.2</mu>
                <mu2>0.2</mu2>
              </ode>
              <torsional>
                <ode/>
              </torsional>
            </friction>
            <bounce/>
          </surface>
          <max_contacts>10</max_contacts>
        </collision>
        <visual name='front_base_fixed_joint_lump__F_link_0_visual'>
          <pose>0 0 0.015 0 -0 0</pose>
          <geometry>
            <mesh>
              <scale>1 1 1</scale>
              <uri>/home/puze/catkin_ws/src/iiwas_core/iiwas_description/meshes/visual/link_0.stl</uri>
            </mesh>
          </geometry>
          <material>
            <script>
              <name>Gazebo/Grey</name>
              <uri>file://media/materials/scripts/gazebo.material</uri>
            </script>
          </material>
        </visual>
        <velocity_decay/>
        <kinematic>1</kinematic>
        <gravity>1</gravity>
        <velocity_decay/>
        <self_collide>0</self_collide>
        <enable_wind>0</enable_wind>
      </link>
      <joint name='F_joint_1' type='revolute'>
        <pose relative_to='front_base'>0 0 0.1725 0 -0 0</pose>
        <parent>front_base</parent>
        <child>F_link_1</child>
        <axis>
          <xyz>0 0 1</xyz>
          <limit>
            <lower>-2.96706</lower>
            <upper>2.96706</upper>
            <effort>320</effort>
            <velocity>1.48353</velocity>
          </limit>
          <dynamics>
            <damping>0.5</damping>
            <friction>0</friction>
            <spring_reference>0</spring_reference>
            <spring_stiffness>0</spring_stiffness>
          </dynamics>
        </axis>
      </joint>
      <link name='F_link_1'>
        <pose relative_to='F_joint_1'>0 0 0 0 -0 0</pose>
        <inertial>
          <pose>0 -0.03 0.12 0 -0 0</pose>
          <mass>3.94781</mass>
          <inertia>
            <ixx>0.1</ixx>
            <ixy>0</ixy>
            <ixz>0</ixz>
            <iyy>0.09</iyy>
            <iyz>0</iyz>
            <izz>0.02</izz>
          </inertia>
        </inertial>
        <collision name='F_link_1_collision'>
          <pose>0 0 0 0 -0 0</pose>
          <geometry>
            <mesh>
              <scale>1 1 1</scale>
              <uri>/home/puze/catkin_ws/src/iiwas_core/iiwas_description/meshes/collision/link_1.stl</uri>
            </mesh>
          </geometry>
          <surface>
            <contact>
              <ode/>
            </contact>
            <friction>
              <ode>
                <mu>0.2</mu>
                <mu2>0.2</mu2>
              </ode>
              <torsional>
                <ode/>
              </torsional>
            </friction>
            <bounce/>
          </surface>
          <max_contacts>10</max_contacts>
        </collision>
        <visual name='F_link_1_visual'>
          <pose>0 0 0 0 -0 0</pose>
          <geometry>
            <mesh>
              <scale>1 1 1</scale>
              <uri>/home/puze/catkin_ws/src/iiwas_core/iiwas_description/meshes/visual/link_1.stl</uri>
            </mesh>
          </geometry>
          <material>
            <script>
              <name>Gazebo/Orange</name>
              <uri>file://media/materials/scripts/gazebo.material</uri>
            </script>
          </material>
        </visual>
        <gravity>1</gravity>
        <velocity_decay/>
        <self_collide>0</self_collide>
        <enable_wind>0</enable_wind>
        <kinematic>0</kinematic>
      </link>
      <joint name='F_joint_2' type='revolute'>
        <pose relative_to='F_link_1'>0 0 0.2025 1.5708 -0 3.14159</pose>
        <parent>F_link_1</parent>
        <child>F_link_2</child>
        <axis>
          <xyz>0 0 1</xyz>
          <limit>
            <lower>-2.0944</lower>
            <upper>2.0944</upper>
            <effort>320</effort>
            <velocity>1.48353</velocity>
          </limit>
          <dynamics>
            <damping>0.5</damping>
            <friction>0</friction>
            <spring_reference>0</spring_reference>
            <spring_stiffness>0</spring_stiffness>
          </dynamics>
        </axis>
      </joint>
      <link name='F_link_2'>
        <pose relative_to='F_joint_2'>0 0 0 0 -0 0</pose>
        <inertial>
          <pose>0.0003 0.059 0.042 0 -0 0</pose>
          <mass>4.50275</mass>
          <inertia>
            <ixx>0.05</ixx>
            <ixy>0</ixy>
            <ixz>0</ixz>
            <iyy>0.018</iyy>
            <iyz>0</iyz>
            <izz>0.044</izz>
          </inertia>
        </inertial>
        <collision name='F_link_2_collision'>
          <pose>0 0 0 0 -0 0</pose>
          <geometry>
            <mesh>
              <scale>1 1 1</scale>
              <uri>/home/puze/catkin_ws/src/iiwas_core/iiwas_description/meshes/collision/link_2.stl</uri>
            </mesh>
          </geometry>
          <surface>
            <contact>
              <ode/>
            </contact>
            <friction>
              <ode>
                <mu>0.2</mu>
                <mu2>0.2</mu2>
              </ode>
              <torsional>
                <ode/>
              </torsional>
            </friction>
            <bounce/>
          </surface>
          <max_contacts>10</max_contacts>
        </collision>
        <visual name='F_link_2_visual'>
          <pose>0 0 0 0 -0 0</pose>
          <geometry>
            <mesh>
              <scale>1 1 1</scale>
              <uri>/home/puze/catkin_ws/src/iiwas_core/iiwas_description/meshes/visual/link_2.stl</uri>
            </mesh>
          </geometry>
          <material>
            <script>
              <name>Gazebo/Orange</name>
              <uri>file://media/materials/scripts/gazebo.material</uri>
            </script>
          </material>
        </visual>
        <gravity>1</gravity>
        <velocity_decay/>
        <self_collide>0</self_collide>
        <enable_wind>0</enable_wind>
        <kinematic>0</kinematic>
      </link>
      <joint name='F_joint_3' type='revolute'>
        <pose relative_to='F_link_2'>0 0.2045 0 1.5708 -0 3.14159</pose>
        <parent>F_link_2</parent>
        <child>F_link_3</child>
        <axis>
          <xyz>0 0 1</xyz>
          <limit>
            <lower>-2.96706</lower>
            <upper>2.96706</upper>
            <effort>176</effort>
            <velocity>1.74533</velocity>
          </limit>
          <dynamics>
            <damping>0.5</damping>
            <friction>0</friction>
            <spring_reference>0</spring_reference>
            <spring_stiffness>0</spring_stiffness>
          </dynamics>
        </axis>
      </joint>
      <link name='F_link_3'>
        <pose relative_to='F_joint_3'>0 0 0 0 -0 0</pose>
        <inertial>
          <pose>0 0.03 0.13 0 -0 0</pose>
          <mass>2.4552</mass>
          <inertia>
            <ixx>0.08</ixx>
            <ixy>0</ixy>
            <ixz>0</ixz>
            <iyy>0.075</iyy>
            <iyz>0</iyz>
            <izz>0.01</izz>
          </inertia>
        </inertial>
        <collision name='F_link_3_collision'>
          <pose>0 0 0 0 -0 0</pose>
          <geometry>
            <mesh>
              <scale>1 1 1</scale>
              <uri>/home/puze/catkin_ws/src/iiwas_core/iiwas_description/meshes/collision/link_3.stl</uri>
            </mesh>
          </geometry>
          <surface>
            <contact>
              <ode/>
            </contact>
            <friction>
              <ode>
                <mu>0.2</mu>
                <mu2>0.2</mu2>
              </ode>
              <torsional>
                <ode/>
              </torsional>
            </friction>
            <bounce/>
          </surface>
          <max_contacts>10</max_contacts>
        </collision>
        <visual name='F_link_3_visual'>
          <pose>0 0 0 0 -0 0</pose>
          <geometry>
            <mesh>
              <scale>1 1 1</scale>
              <uri>/home/puze/catkin_ws/src/iiwas_core/iiwas_description/meshes/visual/link_3.stl</uri>
            </mesh>
          </geometry>
          <material>
            <script>
              <name>Gazebo/Orange</name>
              <uri>file://media/materials/scripts/gazebo.material</uri>
            </script>
          </material>
        </visual>
        <gravity>1</gravity>
        <velocity_decay/>
        <self_collide>0</self_collide>
        <enable_wind>0</enable_wind>
        <kinematic>0</kinematic>
      </link>
      <joint name='F_joint_4' type='revolute'>
        <pose relative_to='F_link_3'>0 0 0.2155 1.5708 -0 0</pose>
        <parent>F_link_3</parent>
        <child>F_link_4</child>
        <axis>
          <xyz>0 0 1</xyz>
          <limit>
            <lower>-2.0944</lower>
            <upper>2.0944</upper>
            <effort>176</effort>
            <velocity>1.309</velocity>
          </limit>
          <dynamics>
            <damping>0.5</damping>
            <friction>0</friction>
            <spring_reference>0</spring_reference>
            <spring_stiffness>0</spring_stiffness>
          </dynamics>
        </axis>
      </joint>
      <link name='F_link_4'>
        <pose relative_to='F_joint_4'>0 0 0 0 -0 0</pose>
        <inertial>
          <pose>0 0.067 0.034 0 -0 0</pose>
          <mass>2.61155</mass>
          <inertia>
            <ixx>0.03</ixx>
            <ixy>0</ixy>
            <ixz>0</ixz>
            <iyy>0.01</iyy>
            <iyz>0</iyz>
            <izz>0.029</izz>
          </inertia>
        </inertial>
        <collision name='F_link_4_collision'>
          <pose>0 0 0 0 -0 0</pose>
          <geometry>
            <mesh>
              <scale>1 1 1</scale>
              <uri>/home/puze/catkin_ws/src/iiwas_core/iiwas_description/meshes/collision/link_4.stl</uri>
            </mesh>
          </geometry>
          <surface>
            <contact>
              <ode/>
            </contact>
            <friction>
              <ode>
                <mu>0.2</mu>
                <mu2>0.2</mu2>
              </ode>
              <torsional>
                <ode/>
              </torsional>
            </friction>
            <bounce/>
          </surface>
          <max_contacts>10</max_contacts>
        </collision>
        <visual name='F_link_4_visual'>
          <pose>0 0 0 0 -0 0</pose>
          <geometry>
            <mesh>
              <scale>1 1 1</scale>
              <uri>/home/puze/catkin_ws/src/iiwas_core/iiwas_description/meshes/visual/link_4.stl</uri>
            </mesh>
          </geometry>
          <material>
            <script>
              <name>Gazebo/Orange</name>
              <uri>file://media/materials/scripts/gazebo.material</uri>
            </script>
          </material>
        </visual>
        <gravity>1</gravity>
        <velocity_decay/>
        <self_collide>0</self_collide>
        <enable_wind>0</enable_wind>
        <kinematic>0</kinematic>
      </link>
      <joint name='F_joint_5' type='revolute'>
        <pose relative_to='F_link_4'>0 0.1845 0 1.5708 -0 3.14159</pose>
        <parent>F_link_4</parent>
        <child>F_link_5</child>
        <axis>
          <xyz>0 0 1</xyz>
          <limit>
            <lower>-2.96706</lower>
            <upper>2.96706</upper>
            <effort>110</effort>
            <velocity>2.26893</velocity>
          </limit>
          <dynamics>
            <damping>0.5</damping>
            <friction>0</friction>
            <spring_reference>0</spring_reference>
            <spring_stiffness>0</spring_stiffness>
          </dynamics>
        </axis>
      </joint>
      <link name='F_link_5'>
        <pose relative_to='F_joint_5'>0 0 0 0 -0 0</pose>
        <inertial>
          <pose>0.0001 0.021 0.076 0 -0 0</pose>
          <mass>3.41001</mass>
          <inertia>
            <ixx>0.02</ixx>
            <ixy>0</ixy>
            <ixz>0</ixz>
            <iyy>0.018</iyy>
            <iyz>0</iyz>
            <izz>0.005</izz>
          </inertia>
        </inertial>
        <collision name='F_link_5_collision'>
          <pose>0 0 0 0 -0 0</pose>
          <geometry>
            <mesh>
              <scale>1 1 1</scale>
              <uri>/home/puze/catkin_ws/src/iiwas_core/iiwas_description/meshes/collision/link_5.stl</uri>
            </mesh>
          </geometry>
          <surface>
            <contact>
              <ode/>
            </contact>
            <friction>
              <ode>
                <mu>0.2</mu>
                <mu2>0.2</mu2>
              </ode>
              <torsional>
                <ode/>
              </torsional>
            </friction>
            <bounce/>
          </surface>
          <max_contacts>10</max_contacts>
        </collision>
        <visual name='F_link_5_visual'>
          <pose>0 0 0 0 -0 0</pose>
          <geometry>
            <mesh>
              <scale>1 1 1</scale>
              <uri>/home/puze/catkin_ws/src/iiwas_core/iiwas_description/meshes/visual/link_5.stl</uri>
            </mesh>
          </geometry>
          <material>
            <script>
              <name>Gazebo/Orange</name>
              <uri>file://media/materials/scripts/gazebo.material</uri>
            </script>
          </material>
        </visual>
        <gravity>1</gravity>
        <velocity_decay/>
        <self_collide>0</self_collide>
        <enable_wind>0</enable_wind>
        <kinematic>0</kinematic>
      </link>
      <joint name='F_joint_6' type='revolute'>
        <pose relative_to='F_link_5'>0 0 0.2155 1.5708 -0 0</pose>
        <parent>F_link_5</parent>
        <child>F_link_6</child>
        <axis>
          <xyz>0 0 1</xyz>
          <limit>
            <lower>-2.0944</lower>
            <upper>2.0944</upper>
            <effort>40</effort>
            <velocity>2.35619</velocity>
          </limit>
          <dynamics>
            <damping>0.5</damping>
            <friction>0</friction>
            <spring_reference>0</spring_reference>
            <spring_stiffness>0</spring_stiffness>
          </dynamics>
        </axis>
      </joint>
      <link name='F_link_6'>
        <pose relative_to='F_joint_6'>0 0 0 0 -0 0</pose>
        <inertial>
          <pose>0 0.0006 0.0004 0 -0 0</pose>
          <mass>3.38795</mass>
          <inertia>
            <ixx>0.005</ixx>
            <ixy>0</ixy>
            <ixz>0</ixz>
            <iyy>0.0036</iyy>
            <iyz>0</iyz>
            <izz>0.0047</izz>
          </inertia>
        </inertial>
        <collision name='F_link_6_collision'>
          <pose>0 0 0 0 -0 0</pose>
          <geometry>
            <mesh>
              <scale>1 1 1</scale>
              <uri>/home/puze/catkin_ws/src/iiwas_core/iiwas_description/meshes/collision/link_6.stl</uri>
            </mesh>
          </geometry>
          <surface>
            <contact>
              <ode/>
            </contact>
            <friction>
              <ode>
                <mu>0.2</mu>
                <mu2>0.2</mu2>
              </ode>
              <torsional>
                <ode/>
              </torsional>
            </friction>
            <bounce/>
          </surface>
          <max_contacts>10</max_contacts>
        </collision>
        <visual name='F_link_6_visual'>
          <pose>0 0 0 0 -0 0</pose>
          <geometry>
            <mesh>
              <scale>1 1 1</scale>
              <uri>/home/puze/catkin_ws/src/iiwas_core/iiwas_description/meshes/visual/link_6.stl</uri>
            </mesh>
          </geometry>
          <material>
            <script>
              <name>Gazebo/Orange</name>
              <uri>file://media/materials/scripts/gazebo.material</uri>
            </script>
          </material>
        </visual>
        <gravity>1</gravity>
        <velocity_decay/>
        <self_collide>0</self_collide>
        <enable_wind>0</enable_wind>
        <kinematic>0</kinematic>
      </link>
      <joint name='F_joint_7' type='revolute'>
        <pose relative_to='F_link_6'>0 0.081 0 1.5708 -0 3.14159</pose>
        <parent>F_link_6</parent>
        <child>F_link_7</child>
        <axis>
          <xyz>0 0 1</xyz>
          <limit>
            <lower>-3.05433</lower>
            <upper>3.05433</upper>
            <effort>40</effort>
            <velocity>2.35619</velocity>
          </limit>
          <dynamics>
            <damping>0.5</damping>
            <friction>0</friction>
            <spring_reference>0</spring_reference>
            <spring_stiffness>0</spring_stiffness>
          </dynamics>
        </axis>
      </joint>
      <link name='F_link_7'>
        <pose relative_to='F_joint_7'>0 0 0 0 -0 0</pose>
        <inertial>
          <pose>0 0 0.02 0 -0 0</pose>
          <mass>0.354321</mass>
          <inertia>
            <ixx>0.001</ixx>
            <ixy>0</ixy>
            <ixz>0</ixz>
            <iyy>0.001</iyy>
            <iyz>0</iyz>
            <izz>0.001</izz>
          </inertia>
        </inertial>
        <collision name='F_link_7_collision'>
          <pose>0 0 0 0 -0 0</pose>
          <geometry>
            <mesh>
              <scale>1 1 1</scale>
              <uri>/home/puze/catkin_ws/src/iiwas_core/iiwas_description/meshes/collision/link_7.stl</uri>
            </mesh>
          </geometry>
          <surface>
            <contact>
              <ode/>
            </contact>
            <friction>
              <ode>
                <mu>0.2</mu>
                <mu2>0.2</mu2>
              </ode>
              <torsional>
                <ode/>
              </torsional>
            </friction>
            <bounce/>
          </surface>
          <max_contacts>10</max_contacts>
        </collision>
        <visual name='F_link_7_visual'>
          <pose>0 0 0 0 -0 0</pose>
          <geometry>
            <mesh>
              <scale>1 1 1</scale>
              <uri>/home/puze/catkin_ws/src/iiwas_core/iiwas_description/meshes/visual/link_7.stl</uri>
            </mesh>
          </geometry>
          <material>
            <script>
              <name>Gazebo/Grey</name>
              <uri>file://media/materials/scripts/gazebo.material</uri>
            </script>
          </material>
        </visual>
        <gravity>1</gravity>
        <velocity_decay/>
        <self_collide>0</self_collide>
        <enable_wind>0</enable_wind>
        <kinematic>0</kinematic>
      </link>
      <static>0</static>
      <plugin name='gazebo_ros_control' filename='libgazebo_ros_control.so'>
        <robotNamespace>/iiwa_front/</robotNamespace>
      </plugin>
      <pose>0.190001 0.813 0.014951 0 1.4e-05 0</pose>
    </model>
    <model name='iiwa_back'>
      <link name='back_base'>
        <inertial>
          <pose>-0.1 0 0.085 0 -0 0</pose>
          <mass>5</mass>
          <inertia>
            <ixx>0.05</ixx>
            <ixy>0</ixy>
            <ixz>-6.93889e-18</ixz>
            <iyy>0.06</iyy>
            <iyz>0</iyz>
            <izz>0.03</izz>
          </inertia>
        </inertial>
        <collision name='back_base_fixed_joint_lump__B_link_0_collision'>
          <pose>0 0 0.015 0 -0 0</pose>
          <geometry>
            <mesh>
              <scale>1 1 1</scale>
              <uri>/home/puze/catkin_ws/src/iiwas_core/iiwas_description/meshes/collision/link_0.stl</uri>
            </mesh>
          </geometry>
          <surface>
            <contact>
              <ode/>
            </contact>
            <friction>
              <ode>
                <mu>0.2</mu>
                <mu2>0.2</mu2>
              </ode>
              <torsional>
                <ode/>
              </torsional>
            </friction>
            <bounce/>
          </surface>
          <max_contacts>10</max_contacts>
        </collision>
        <visual name='back_base_fixed_joint_lump__B_link_0_visual'>
          <pose>0 0 0.015 0 -0 0</pose>
          <geometry>
            <mesh>
              <scale>1 1 1</scale>
              <uri>/home/puze/catkin_ws/src/iiwas_core/iiwas_description/meshes/visual/link_0.stl</uri>
            </mesh>
          </geometry>
          <material>
            <script>
              <name>Gazebo/Grey</name>
              <uri>file://media/materials/scripts/gazebo.material</uri>
            </script>
          </material>
        </visual>
        <velocity_decay/>
        <kinematic>1</kinematic>
        <gravity>1</gravity>
        <velocity_decay/>
        <self_collide>0</self_collide>
        <enable_wind>0</enable_wind>
      </link>
      <joint name='B_joint_1' type='revolute'>
        <pose relative_to='back_base'>0 0 0.1725 0 -0 0</pose>
        <parent>back_base</parent>
        <child>B_link_1</child>
        <axis>
          <xyz>0 0 1</xyz>
          <limit>
            <lower>-2.96706</lower>
            <upper>2.96706</upper>
            <effort>320</effort>
            <velocity>1.48353</velocity>
          </limit>
          <dynamics>
            <damping>0.5</damping>
            <friction>0</friction>
            <spring_reference>0</spring_reference>
            <spring_stiffness>0</spring_stiffness>
          </dynamics>
        </axis>
      </joint>
      <link name='B_link_1'>
        <pose relative_to='B_joint_1'>0 0 0 0 -0 0</pose>
        <inertial>
          <pose>0 -0.03 0.12 0 -0 0</pose>
          <mass>3.94781</mass>
          <inertia>
            <ixx>0.1</ixx>
            <ixy>0</ixy>
            <ixz>0</ixz>
            <iyy>0.09</iyy>
            <iyz>0</iyz>
            <izz>0.02</izz>
          </inertia>
        </inertial>
        <collision name='B_link_1_collision'>
          <pose>0 0 0 0 -0 0</pose>
          <geometry>
            <mesh>
              <scale>1 1 1</scale>
              <uri>/home/puze/catkin_ws/src/iiwas_core/iiwas_description/meshes/collision/link_1.stl</uri>
            </mesh>
          </geometry>
          <surface>
            <contact>
              <ode/>
            </contact>
            <friction>
              <ode>
                <mu>0.2</mu>
                <mu2>0.2</mu2>
              </ode>
              <torsional>
                <ode/>
              </torsional>
            </friction>
            <bounce/>
          </surface>
          <max_contacts>10</max_contacts>
        </collision>
        <visual name='B_link_1_visual'>
          <pose>0 0 0 0 -0 0</pose>
          <geometry>
            <mesh>
              <scale>1 1 1</scale>
              <uri>/home/puze/catkin_ws/src/iiwas_core/iiwas_description/meshes/visual/link_1.stl</uri>
            </mesh>
          </geometry>
          <material>
            <script>
              <name>Gazebo/Orange</name>
              <uri>file://media/materials/scripts/gazebo.material</uri>
            </script>
          </material>
        </visual>
        <gravity>1</gravity>
        <velocity_decay/>
        <self_collide>0</self_collide>
        <enable_wind>0</enable_wind>
        <kinematic>0</kinematic>
      </link>
      <joint name='B_joint_2' type='revolute'>
        <pose relative_to='B_link_1'>0 0 0.2025 1.5708 -0 3.14159</pose>
        <parent>B_link_1</parent>
        <child>B_link_2</child>
        <axis>
          <xyz>0 0 1</xyz>
          <limit>
            <lower>-2.0944</lower>
            <upper>2.0944</upper>
            <effort>320</effort>
            <velocity>1.48353</velocity>
          </limit>
          <dynamics>
            <damping>0.5</damping>
            <friction>0</friction>
            <spring_reference>0</spring_reference>
            <spring_stiffness>0</spring_stiffness>
          </dynamics>
        </axis>
      </joint>
      <link name='B_link_2'>
        <pose relative_to='B_joint_2'>0 0 0 0 -0 0</pose>
        <inertial>
          <pose>0.0003 0.059 0.042 0 -0 0</pose>
          <mass>4.50275</mass>
          <inertia>
            <ixx>0.05</ixx>
            <ixy>0</ixy>
            <ixz>0</ixz>
            <iyy>0.018</iyy>
            <iyz>0</iyz>
            <izz>0.044</izz>
          </inertia>
        </inertial>
        <collision name='B_link_2_collision'>
          <pose>0 0 0 0 -0 0</pose>
          <geometry>
            <mesh>
              <scale>1 1 1</scale>
              <uri>/home/puze/catkin_ws/src/iiwas_core/iiwas_description/meshes/collision/link_2.stl</uri>
            </mesh>
          </geometry>
          <surface>
            <contact>
              <ode/>
            </contact>
            <friction>
              <ode>
                <mu>0.2</mu>
                <mu2>0.2</mu2>
              </ode>
              <torsional>
                <ode/>
              </torsional>
            </friction>
            <bounce/>
          </surface>
          <max_contacts>10</max_contacts>
        </collision>
        <visual name='B_link_2_visual'>
          <pose>0 0 0 0 -0 0</pose>
          <geometry>
            <mesh>
              <scale>1 1 1</scale>
              <uri>/home/puze/catkin_ws/src/iiwas_core/iiwas_description/meshes/visual/link_2.stl</uri>
            </mesh>
          </geometry>
          <material>
            <script>
              <name>Gazebo/Orange</name>
              <uri>file://media/materials/scripts/gazebo.material</uri>
            </script>
          </material>
        </visual>
        <gravity>1</gravity>
        <velocity_decay/>
        <self_collide>0</self_collide>
        <enable_wind>0</enable_wind>
        <kinematic>0</kinematic>
      </link>
      <joint name='B_joint_3' type='revolute'>
        <pose relative_to='B_link_2'>0 0.2045 0 1.5708 -0 3.14159</pose>
        <parent>B_link_2</parent>
        <child>B_link_3</child>
        <axis>
          <xyz>0 0 1</xyz>
          <limit>
            <lower>-2.96706</lower>
            <upper>2.96706</upper>
            <effort>176</effort>
            <velocity>1.74533</velocity>
          </limit>
          <dynamics>
            <damping>0.5</damping>
            <friction>0</friction>
            <spring_reference>0</spring_reference>
            <spring_stiffness>0</spring_stiffness>
          </dynamics>
        </axis>
      </joint>
      <link name='B_link_3'>
        <pose relative_to='B_joint_3'>0 0 0 0 -0 0</pose>
        <inertial>
          <pose>0 0.03 0.13 0 -0 0</pose>
          <mass>2.4552</mass>
          <inertia>
            <ixx>0.08</ixx>
            <ixy>0</ixy>
            <ixz>0</ixz>
            <iyy>0.075</iyy>
            <iyz>0</iyz>
            <izz>0.01</izz>
          </inertia>
        </inertial>
        <collision name='B_link_3_collision'>
          <pose>0 0 0 0 -0 0</pose>
          <geometry>
            <mesh>
              <scale>1 1 1</scale>
              <uri>/home/puze/catkin_ws/src/iiwas_core/iiwas_description/meshes/collision/link_3.stl</uri>
            </mesh>
          </geometry>
          <surface>
            <contact>
              <ode/>
            </contact>
            <friction>
              <ode>
                <mu>0.2</mu>
                <mu2>0.2</mu2>
              </ode>
              <torsional>
                <ode/>
              </torsional>
            </friction>
            <bounce/>
          </surface>
          <max_contacts>10</max_contacts>
        </collision>
        <visual name='B_link_3_visual'>
          <pose>0 0 0 0 -0 0</pose>
          <geometry>
            <mesh>
              <scale>1 1 1</scale>
              <uri>/home/puze/catkin_ws/src/iiwas_core/iiwas_description/meshes/visual/link_3.stl</uri>
            </mesh>
          </geometry>
          <material>
            <script>
              <name>Gazebo/Orange</name>
              <uri>file://media/materials/scripts/gazebo.material</uri>
            </script>
          </material>
        </visual>
        <gravity>1</gravity>
        <velocity_decay/>
        <self_collide>0</self_collide>
        <enable_wind>0</enable_wind>
        <kinematic>0</kinematic>
      </link>
      <joint name='B_joint_4' type='revolute'>
        <pose relative_to='B_link_3'>0 0 0.2155 1.5708 -0 0</pose>
        <parent>B_link_3</parent>
        <child>B_link_4</child>
        <axis>
          <xyz>0 0 1</xyz>
          <limit>
            <lower>-2.0944</lower>
            <upper>2.0944</upper>
            <effort>176</effort>
            <velocity>1.309</velocity>
          </limit>
          <dynamics>
            <damping>0.5</damping>
            <friction>0</friction>
            <spring_reference>0</spring_reference>
            <spring_stiffness>0</spring_stiffness>
          </dynamics>
        </axis>
      </joint>
      <link name='B_link_4'>
        <pose relative_to='B_joint_4'>0 0 0 0 -0 0</pose>
        <inertial>
          <pose>0 0.067 0.034 0 -0 0</pose>
          <mass>2.61155</mass>
          <inertia>
            <ixx>0.03</ixx>
            <ixy>0</ixy>
            <ixz>0</ixz>
            <iyy>0.01</iyy>
            <iyz>0</iyz>
            <izz>0.029</izz>
          </inertia>
        </inertial>
        <collision name='B_link_4_collision'>
          <pose>0 0 0 0 -0 0</pose>
          <geometry>
            <mesh>
              <scale>1 1 1</scale>
              <uri>/home/puze/catkin_ws/src/iiwas_core/iiwas_description/meshes/collision/link_4.stl</uri>
            </mesh>
          </geometry>
          <surface>
            <contact>
              <ode/>
            </contact>
            <friction>
              <ode>
                <mu>0.2</mu>
                <mu2>0.2</mu2>
              </ode>
              <torsional>
                <ode/>
              </torsional>
            </friction>
            <bounce/>
          </surface>
          <max_contacts>10</max_contacts>
        </collision>
        <visual name='B_link_4_visual'>
          <pose>0 0 0 0 -0 0</pose>
          <geometry>
            <mesh>
              <scale>1 1 1</scale>
              <uri>/home/puze/catkin_ws/src/iiwas_core/iiwas_description/meshes/visual/link_4.stl</uri>
            </mesh>
          </geometry>
          <material>
            <script>
              <name>Gazebo/Orange</name>
              <uri>file://media/materials/scripts/gazebo.material</uri>
            </script>
          </material>
        </visual>
        <gravity>1</gravity>
        <velocity_decay/>
        <self_collide>0</self_collide>
        <enable_wind>0</enable_wind>
        <kinematic>0</kinematic>
      </link>
      <joint name='B_joint_5' type='revolute'>
        <pose relative_to='B_link_4'>0 0.1845 0 1.5708 -0 3.14159</pose>
        <parent>B_link_4</parent>
        <child>B_link_5</child>
        <axis>
          <xyz>0 0 1</xyz>
          <limit>
            <lower>-2.96706</lower>
            <upper>2.96706</upper>
            <effort>110</effort>
            <velocity>2.26893</velocity>
          </limit>
          <dynamics>
            <damping>0.5</damping>
            <friction>0</friction>
            <spring_reference>0</spring_reference>
            <spring_stiffness>0</spring_stiffness>
          </dynamics>
        </axis>
      </joint>
      <link name='B_link_5'>
        <pose relative_to='B_joint_5'>0 0 0 0 -0 0</pose>
        <inertial>
          <pose>0.0001 0.021 0.076 0 -0 0</pose>
          <mass>3.41001</mass>
          <inertia>
            <ixx>0.02</ixx>
            <ixy>0</ixy>
            <ixz>0</ixz>
            <iyy>0.018</iyy>
            <iyz>0</iyz>
            <izz>0.005</izz>
          </inertia>
        </inertial>
        <collision name='B_link_5_collision'>
          <pose>0 0 0 0 -0 0</pose>
          <geometry>
            <mesh>
              <scale>1 1 1</scale>
              <uri>/home/puze/catkin_ws/src/iiwas_core/iiwas_description/meshes/collision/link_5.stl</uri>
            </mesh>
          </geometry>
          <surface>
            <contact>
              <ode/>
            </contact>
            <friction>
              <ode>
                <mu>0.2</mu>
                <mu2>0.2</mu2>
              </ode>
              <torsional>
                <ode/>
              </torsional>
            </friction>
            <bounce/>
          </surface>
          <max_contacts>10</max_contacts>
        </collision>
        <visual name='B_link_5_visual'>
          <pose>0 0 0 0 -0 0</pose>
          <geometry>
            <mesh>
              <scale>1 1 1</scale>
              <uri>/home/puze/catkin_ws/src/iiwas_core/iiwas_description/meshes/visual/link_5.stl</uri>
            </mesh>
          </geometry>
          <material>
            <script>
              <name>Gazebo/Orange</name>
              <uri>file://media/materials/scripts/gazebo.material</uri>
            </script>
          </material>
        </visual>
        <gravity>1</gravity>
        <velocity_decay/>
        <self_collide>0</self_collide>
        <enable_wind>0</enable_wind>
        <kinematic>0</kinematic>
      </link>
      <joint name='B_joint_6' type='revolute'>
        <pose relative_to='B_link_5'>0 0 0.2155 1.5708 -0 0</pose>
        <parent>B_link_5</parent>
        <child>B_link_6</child>
        <axis>
          <xyz>0 0 1</xyz>
          <limit>
            <lower>-2.0944</lower>
            <upper>2.0944</upper>
            <effort>40</effort>
            <velocity>2.35619</velocity>
          </limit>
          <dynamics>
            <damping>0.5</damping>
            <friction>0</friction>
            <spring_reference>0</spring_reference>
            <spring_stiffness>0</spring_stiffness>
          </dynamics>
        </axis>
      </joint>
      <link name='B_link_6'>
        <pose relative_to='B_joint_6'>0 0 0 0 -0 0</pose>
        <inertial>
          <pose>0 0.0006 0.0004 0 -0 0</pose>
          <mass>3.38795</mass>
          <inertia>
            <ixx>0.005</ixx>
            <ixy>0</ixy>
            <ixz>0</ixz>
            <iyy>0.0036</iyy>
            <iyz>0</iyz>
            <izz>0.0047</izz>
          </inertia>
        </inertial>
        <collision name='B_link_6_collision'>
          <pose>0 0 0 0 -0 0</pose>
          <geometry>
            <mesh>
              <scale>1 1 1</scale>
              <uri>/home/puze/catkin_ws/src/iiwas_core/iiwas_description/meshes/collision/link_6.stl</uri>
            </mesh>
          </geometry>
          <surface>
            <contact>
              <ode/>
            </contact>
            <friction>
              <ode>
                <mu>0.2</mu>
                <mu2>0.2</mu2>
              </ode>
              <torsional>
                <ode/>
              </torsional>
            </friction>
            <bounce/>
          </surface>
          <max_contacts>10</max_contacts>
        </collision>
        <visual name='B_link_6_visual'>
          <pose>0 0 0 0 -0 0</pose>
          <geometry>
            <mesh>
              <scale>1 1 1</scale>
              <uri>/home/puze/catkin_ws/src/iiwas_core/iiwas_description/meshes/visual/link_6.stl</uri>
            </mesh>
          </geometry>
          <material>
            <script>
              <name>Gazebo/Orange</name>
              <uri>file://media/materials/scripts/gazebo.material</uri>
            </script>
          </material>
        </visual>
        <gravity>1</gravity>
        <velocity_decay/>
        <self_collide>0</self_collide>
        <enable_wind>0</enable_wind>
        <kinematic>0</kinematic>
      </link>
      <joint name='B_joint_7' type='revolute'>
        <pose relative_to='B_link_6'>0 0.081 0 1.5708 -0 3.14159</pose>
        <parent>B_link_6</parent>
        <child>B_link_7</child>
        <axis>
          <xyz>0 0 1</xyz>
          <limit>
            <lower>-3.05433</lower>
            <upper>3.05433</upper>
            <effort>40</effort>
            <velocity>2.35619</velocity>
          </limit>
          <dynamics>
            <damping>0.5</damping>
            <friction>0</friction>
            <spring_reference>0</spring_reference>
            <spring_stiffness>0</spring_stiffness>
          </dynamics>
        </axis>
      </joint>
      <link name='B_link_7'>
        <pose relative_to='B_joint_7'>0 0 0 0 -0 0</pose>
        <inertial>
          <pose>0 0 0.02 0 -0 0</pose>
          <mass>0.354321</mass>
          <inertia>
            <ixx>0.001</ixx>
            <ixy>0</ixy>
            <ixz>0</ixz>
            <iyy>0.001</iyy>
            <iyz>0</iyz>
            <izz>0.001</izz>
          </inertia>
        </inertial>
        <collision name='B_link_7_collision'>
          <pose>0 0 0 0 -0 0</pose>
          <geometry>
            <mesh>
              <scale>1 1 1</scale>
              <uri>/home/puze/catkin_ws/src/iiwas_core/iiwas_description/meshes/collision/link_7.stl</uri>
            </mesh>
          </geometry>
          <surface>
            <contact>
              <ode/>
            </contact>
            <friction>
              <ode>
                <mu>0.2</mu>
                <mu2>0.2</mu2>
              </ode>
              <torsional>
                <ode/>
              </torsional>
            </friction>
            <bounce/>
          </surface>
          <max_contacts>10</max_contacts>
        </collision>
        <visual name='B_link_7_visual'>
          <pose>0 0 0 0 -0 0</pose>
          <geometry>
            <mesh>
              <scale>1 1 1</scale>
              <uri>/home/puze/catkin_ws/src/iiwas_core/iiwas_description/meshes/visual/link_7.stl</uri>
            </mesh>
          </geometry>
          <material>
            <script>
              <name>Gazebo/Grey</name>
              <uri>file://media/materials/scripts/gazebo.material</uri>
            </script>
          </material>
        </visual>
        <gravity>1</gravity>
        <velocity_decay/>
        <self_collide>0</self_collide>
        <enable_wind>0</enable_wind>
        <kinematic>0</kinematic>
      </link>
      <static>0</static>
      <plugin name='gazebo_ros_control' filename='libgazebo_ros_control.so'>
        <robotNamespace>/iiwa_back/</robotNamespace>
      </plugin>
      <pose>3.198 0.813 0.014952 0 1.4e-05 3.14159</pose>
    </model>
    <state world_name='default'>
      <sim_time>64 695000000</sim_time>
      <real_time>66 715502466</real_time>
      <wall_time>1608234799 699792805</wall_time>
      <iterations>64695</iterations>
      <model name='ground_plane'>
        <pose>0 0 -0.18 0 -0 0</pose>
        <scale>1 1 1</scale>
        <link name='link'>
          <pose>0 0 -0.18 0 -0 0</pose>
          <velocity>0 0 0 0 -0 0</velocity>
          <acceleration>0 0 0 0 -0 0</acceleration>
          <wrench>0 0 0 0 -0 0</wrench>
        </link>
      </model>
      <model name='iiwa_back'>
        <pose>3.198 0.813 0.014952 0 1.4e-05 3.14159</pose>
        <scale>1 1 1</scale>
        <link name='B_link_1'>
          <pose>3.198 0.813 0.187452 0 1.4e-05 3.14159</pose>
          <velocity>-0 0 0 0 -0 0</velocity>
          <acceleration>0 0 -0 0 -0 0</acceleration>
          <wrench>0 0 -0 0 -0 0</wrench>
        </link>
        <link name='B_link_2'>
          <pose>3.198 0.813 0.389952 1.5708 -1.4e-05 -5e-06</pose>
          <velocity>0 0 -0 0 -1e-06 0</velocity>
          <acceleration>0 0 0 0 6e-06 -1.8e-05</acceleration>
          <wrench>0 0 0 0 -0 0</wrench>
        </link>
        <link name='B_link_3'>
          <pose>3.19799 0.813 0.594452 1e-06 1.1e-05 3.14159</pose>
          <velocity>-0 0 -0 0 -1e-06 0</velocity>
          <acceleration>-0 0 0 0 -0 0</acceleration>
          <wrench>-0 0 0 0 -0 0</wrench>
        </link>
        <link name='B_link_4'>
          <pose>3.19799 0.813 0.809952 1.5708 1.2e-05 3.14159</pose>
          <velocity>-0 0 -0 0 -1e-06 0</velocity>
          <acceleration>0 0 0 0 6e-06 6.5e-05</acceleration>
          <wrench>0 0 0 0 -0 0</wrench>
        </link>
        <link name='B_link_5'>
          <pose>3.19799 0.813001 0.994452 -1e-06 -1.4e-05 -5e-06</pose>
          <velocity>-1e-06 0 -0 0 -1e-06 0</velocity>
          <acceleration>0 -0 0 0 -0 0</acceleration>
          <wrench>0 -0 0 0 -0 0</wrench>
        </link>
        <link name='B_link_6'>
          <pose>3.19798 0.813001 1.20995 1.5708 -1.4e-05 -5e-06</pose>
          <velocity>-1e-06 0 -0 0 -3e-06 0</velocity>
          <acceleration>-0 -0 -0 0 2.8e-05 0</acceleration>
          <wrench>-0 -0 -0 0 -0 0</wrench>
        </link>
        <link name='B_link_7'>
          <pose>3.19798 0.813001 1.29095 2e-06 1.2e-05 3.14159</pose>
          <velocity>-1e-06 0 -0 0 -3e-06 0</velocity>
          <acceleration>-0 -0 -0 0 -0 0</acceleration>
          <wrench>-0 -0 -0 0 -0 0</wrench>
        </link>
        <link name='back_base'>
          <pose>3.198 0.813 0.014952 0 1.4e-05 3.14159</pose>
          <velocity>0 0 0 0 -0 0</velocity>
          <acceleration>0 0 -1.962 0 0 -1e-06</acceleration>
          <wrench>0 0 -9.81 0 -0 0</wrench>
        </link>
      </model>
      <model name='iiwa_front'>
        <pose>0.190001 0.813 0.014951 0 1.4e-05 0</pose>
        <scale>1 1 1</scale>
        <link name='F_link_1'>
          <pose>0.190003 0.813 0.187451 0 1.4e-05 0</pose>
          <velocity>0 -0 -0 0 -0 0</velocity>
          <acceleration>0 0 0 0 -0 0</acceleration>
          <wrench>0 0 0 0 -0 0</wrench>
        </link>
        <link name='F_link_2'>
          <pose>0.190006 0.813 0.389951 1.5708 -1.4e-05 3.14159</pose>
          <velocity>0 0 0 0 3e-06 0</velocity>
          <acceleration>0 0 -0 -0 -1.8e-05 -4.2e-05</acceleration>
          <wrench>0 0 -0 0 -0 0</wrench>
        </link>
        <link name='F_link_3'>
          <pose>0.190009 0.813001 0.594451 1e-06 1.2e-05 -3e-06</pose>
          <velocity>1e-06 -0 -0 -0 3e-06 1e-06</velocity>
          <acceleration>-0 -0 0 0 -0 0</acceleration>
          <wrench>-0 -0 0 0 -0 0</wrench>
        </link>
        <link name='F_link_4'>
          <pose>0.190012 0.813 0.809951 1.5708 1.2e-05 -3e-06</pose>
          <velocity>1e-06 -0 -0 0 4e-06 1e-06</velocity>
          <acceleration>-0 -0 -0 0 -1.4e-05 8.1e-05</acceleration>
          <wrench>-0 -0 -0 0 -0 0</wrench>
        </link>
        <link name='F_link_5'>
          <pose>0.190014 0.812999 0.994451 -2e-06 -1.5e-05 3.14159</pose>
          <velocity>2e-06 -0 -0 0 4e-06 0</velocity>
          <acceleration>-0 -0 -0 0 -0 0</acceleration>
          <wrench>-0 -0 -0 0 -0 0</wrench>
        </link>
        <link name='F_link_6'>
          <pose>0.190017 0.812999 1.20995 1.5708 -1.5e-05 3.14159</pose>
          <velocity>3e-06 -0 -0 0 4e-06 0</velocity>
          <acceleration>-0 0 -0 0 -5e-06 0</acceleration>
          <wrench>-0 0 -0 0 -0 0</wrench>
        </link>
        <link name='F_link_7'>
          <pose>0.190018 0.812999 1.29095 2e-06 1.2e-05 -3e-06</pose>
          <velocity>3e-06 -0 -0 0 4e-06 0</velocity>
          <acceleration>-0 -0 -0 0 -0 0</acceleration>
          <wrench>-0 -0 -0 0 -0 0</wrench>
        </link>
        <link name='front_base'>
          <pose>0.190001 0.813 0.014951 0 1.4e-05 0</pose>
          <velocity>0 0 0 0 -0 0</velocity>
          <acceleration>0 0 -1.962 0 0 -6e-06</acceleration>
          <wrench>0 0 -9.81 0 -0 0</wrench>
        </link>
      </model>
      <model name='iiwas_frame'>
        <pose>0 0 0 0 -0 0</pose>
        <scale>1 1 1</scale>
        <link name='back_base'>
          <pose>3.198 0.813 0.014952 0 1.4e-05 3.14159</pose>
          <velocity>0 1e-06 -1e-06 9e-05 -6e-06 -0</velocity>
          <acceleration>0.000171 0.00193 -0.002151 0.179521 -0.0114 4e-06</acceleration>
          <wrench>0.000513 0.005791 -0.006453 0 -0 0</wrench>
        </link>
        <link name='front_base'>
          <pose>0.190001 0.813 0.014951 0 1.4e-05 0</pose>
          <velocity>0 2e-06 -1e-06 0.000209 -1.4e-05 0</velocity>
          <acceleration>0.000417 0.004482 -0.001825 0.418059 -0.027785 -9e-06</acceleration>
          <wrench>0.00125 0.013446 -0.005476 0 -0 0</wrench>
        </link>
        <link name='iiwa_frame_origin'>
          <pose>-0.048 -0.076 0 0 -0 0</pose>
          <velocity>-0 0 -0 -0 -0 -0</velocity>
          <acceleration>0 1e-06 -1e-06 -0 -0 -0</acceleration>
          <wrench>0 4.3e-05 -2.2e-05 0 -0 0</wrench>
        </link>
      </model>
      <light name='sun'>
        <pose>0 0 10 0 -0 0</pose>
      </light>
    </state>
    <gui fullscreen='0'>
      <camera name='user_camera'>
        <pose>1.60837 -4.14898 2.28895 -0 0.343643 1.54819</pose>
        <view_controller>orbit</view_controller>
        <projection_type>perspective</projection_type>
      </camera>
    </gui>
  </world>
</sdf>
